[32m2024-02-08 14:54:35 +0100[0m - dagster - [34mDEBUG[0m - __ASSET_JOB - be645b8f-d68f-42bc-8574-9718055a136a - 156005 - LOGS_CAPTURED - Started capturing logs in process (pid: 156005).
[32m2024-02-08 14:54:35 +0100[0m - dagster - [34mDEBUG[0m - __ASSET_JOB - be645b8f-d68f-42bc-8574-9718055a136a - 156005 - analyze_bus_data - STEP_START - Started execution of step "analyze_bus_data".
[32m2024-02-08 14:54:35 +0100[0m - dagster - [34mDEBUG[0m - __ASSET_JOB - be645b8f-d68f-42bc-8574-9718055a136a - analyze_bus_data - Loading file from: ../data/fetch_buses_data using PickledObjectFilesystemIOManager...
[32m2024-02-08 14:54:35 +0100[0m - dagster - [34mDEBUG[0m - __ASSET_JOB - be645b8f-d68f-42bc-8574-9718055a136a - 156005 - analyze_bus_data - ASSET_OBSERVATION - ASSET_OBSERVATION for step analyze_bus_data
[32m2024-02-08 14:54:35 +0100[0m - dagster - [34mDEBUG[0m - __ASSET_JOB - be645b8f-d68f-42bc-8574-9718055a136a - 156005 - analyze_bus_data - LOADED_INPUT - Loaded input "fetch_buses_data" using input manager "base_io_manager"
[32m2024-02-08 14:54:35 +0100[0m - dagster - [34mDEBUG[0m - __ASSET_JOB - be645b8f-d68f-42bc-8574-9718055a136a - 156005 - analyze_bus_data - STEP_INPUT - Got input "fetch_buses_data" of type "Any". (Type check passed).
[32m2024-02-08 14:54:35 +0100[0m - dagster - [34mERROR[0m - [31m__ASSET_JOB - be645b8f-d68f-42bc-8574-9718055a136a - 156005 - analyze_bus_data - STEP_FAILURE - Execution of step "analyze_bus_data" failed.

dagster._core.errors.DagsterExecutionStepExecutionError: Error occurred while executing op "analyze_bus_data"::

KeyError: 'Longitude'

Stack Trace:
  File "/home/janek/miniconda3/envs/bus-analysis/lib/python3.10/site-packages/dagster/_core/execution/plan/utils.py", line 54, in op_execution_error_boundary
    yield
  File "/home/janek/miniconda3/envs/bus-analysis/lib/python3.10/site-packages/dagster/_utils/__init__.py", line 467, in iterate_with_context
    next_output = next(iterator)
  File "/home/janek/miniconda3/envs/bus-analysis/lib/python3.10/site-packages/dagster/_core/execution/plan/compute_generator.py", line 131, in _coerce_op_compute_fn_to_iterator
    result = invoke_compute_fn(
  File "/home/janek/miniconda3/envs/bus-analysis/lib/python3.10/site-packages/dagster/_core/execution/plan/compute_generator.py", line 125, in invoke_compute_fn
    return fn(context, **args_to_pass) if context_arg_provided else fn(**args_to_pass)
  File "/home/janek/kurs_python/zadanie_zaliczeniowe/bus-analysis/bus_analysis/assets.py", line 33, in analyze_bus_data
    buses_data.iloc[i - 1]["Longitude"],
  File "/home/janek/miniconda3/envs/bus-analysis/lib/python3.10/site-packages/pandas/core/series.py", line 1111, in __getitem__
    return self._get_value(key)
  File "/home/janek/miniconda3/envs/bus-analysis/lib/python3.10/site-packages/pandas/core/series.py", line 1227, in _get_value
    loc = self.index.get_loc(label)
  File "/home/janek/miniconda3/envs/bus-analysis/lib/python3.10/site-packages/pandas/core/indexes/base.py", line 3809, in get_loc
    raise KeyError(key) from err

The above exception was caused by the following exception:
KeyError: 'Longitude'

Stack Trace:
  File "/home/janek/miniconda3/envs/bus-analysis/lib/python3.10/site-packages/pandas/core/indexes/base.py", line 3802, in get_loc
    return self._engine.get_loc(casted_key)
  File "index.pyx", line 153, in pandas._libs.index.IndexEngine.get_loc
  File "index.pyx", line 182, in pandas._libs.index.IndexEngine.get_loc
  File "pandas/_libs/hashtable_class_helper.pxi", line 7081, in pandas._libs.hashtable.PyObjectHashTable.get_item
  File "pandas/_libs/hashtable_class_helper.pxi", line 7089, in pandas._libs.hashtable.PyObjectHashTable.get_item
[0m
